Workbook

Sheet Original Source
B3: Date | C3: Financials | D3: Amount
B4: 1.1.2014 | C4: Revenue - Supermarkets | D4: 72
B5: 1.1.2014 | C5: Cogs - Supermarkets | D5: 47
B6: 1.1.2014 | C6: Revenue - Discounters | D6: 37
B7: 1.1.2014 | C7: Cogs - Discounters | D7: 20
B8: 1.1.2014 | C8: Revenue - Grocery | D8: 36
B9: 1.1.2014 | C9: Cogs - Grocery | D9: 17
B10: 1.1.2014 | C10: Revenue - Retail | D10: 57
B11: 1.1.2014 | C11: Cogs - Retail | D11: 32
B12: 1.1.2014 | C12: Operating expenses | D12: 95.4
B13: 1.1.2014 | C13: D&A | D13: 2
B14: 1.1.2014 | C14: Interest expenses | D14: 5
B15: 1.1.2014 | C15: Taxes | D15: 17.29
... B438: 12.1.2016 | C438: Other revenue | D438: 628

Sheet BS 2014
B4: $ in mln | D4: 42004
B5: Receivables - Discounters | D5: 44.609
B6: Receivables - Other | D6: 33.097
B7: Receivables - Grocery | D7: 31.658
B8: Receivables - Retail | D8: 20.146
B9: Receivables - Supermarkets | D9: 14.39
B10: Trade Receivables | D10: 143.9
B12: Inventory - Discounters | D12: 29.75
B13: Inventory - Supermarkets | D13: 18.7
B14: Inventory - Grocery | D14: 16.15
B15: Inventory - Retail | D15: 11.05
B16: Inventory - Other | D16: 9.35
... B58: Liabilities & Equity | D58: 932.1

Sheet BS 2015
B4: $ in mln | C4: Code I | D4: 42369
B5: Receivables - Discounters | C5: R | D5: 40.248
B6: Receivables - Grocery | C6: R | D6: 34.056
B7: Receivables - Other | C7: R | D7: 29.412
B8: Receivables - Retail | C8: R | D8: 27.864
B9: Receivables - Supermarkets | C9: R | D9: 23.22
B10: Trade Receivables | D10: 154.8
B12: Inventory - Discounters | C12: I | D12: 24.84
B13: Inventory - Supermarkets | C13: I | D13: 20.24
B14: Inventory - Grocery | C14: I | D14: 17.48
B15: Inventory - Other | C15: I | D15: 17.48
B16: Inventory - Retail | C16: I | D16: 11.96
B17: Inventory | C17: I | D17: 92
B19: PP&E - Machinery | C19: P | D19: 346.475
B20: PP&E - Other | C20: P | D20: 139.525
B21: PP&E - IT | C21: P | D21: 125.575
B22: PP&E - Vehicles | C22: P | D22: 20.925
B23: PP&E | C23: P | D23: 632.5
B25: Cash - Bank Accounts | C25: C | D25: 13.298
... B27: Cash - Cash at hand | C27: C | D27: 3.052
B28: Cash | D28: 21.8
B30: Other assets | C30: O | D30: 46.9
B31: Other assets | D31: 46.9
B33: Assets | D33: 948
B35: Trade Payables - Discounters | C35: T | D35: 19.981
B36: Trade Payables - Retail | C36: T | D36: 15.847
B37: Trade Payables - Other | C37: T | D37: 14.469
B38: Trade Payables - Grocery | C38: T | D38: 10.335
B39: Trade Payables - Supermarkets | C39: T | D39: 8.268
B40: Trade Payables | D40: 68.9
B42: Provisions - Taxes | C42: P | D42: 17.507
B43: Provisions - Legal | C43: P | D43: 6.601
B44: Provisions - Other | C44: P | D44: 4.592
B45: Provisions | D45: 28.7
B47: Financial Liabilities vs. Banks | C47: F | D47: 610.4
B48: Financial Liabilities | D48: 610.4
B50: Other liabilities | C50: O | D50: 43.3
B51: Other liabilities | D51: 43.3
B53: Retained Earnings | C53: E | D53: 161.525
B54: Minority interest | C54: E | D54: 18.425
...

Sheet BS 2016
B4: $ in mln | C4: Code I | D4: Code II | E4: 42735
B5: Receivables - Discounters | C5: R | D5: A | E5: 44.018
B6: Receivables - Grocery | C6: R | D6: A | E6: 40.632
B7: Receivables - Other | C7: R | D7: A | E7: 32.167
B8: Receivables - Retail | C8: R | D8: A | E8: 27.088
B9: Receivables - Supermarkets | C9: R | D9: A | E9: 25.395
B10: Trade Receivables | E10: 169.3
B12: Inventory - Discounters | C12: I | D12: A | E12: 26.4
B13: Inventory - Supermarkets | C13: I | D13: A | E13: 25.3
B14: Inventory - Grocery | C14: I | D14: A | E14: 20.9
B15: Inventory - Other | C15: I | D15: A | E15: 20.9
B16: Inventory - Retail | C16: I | D16: A | E16: 16.5
B17: Inventory | C17: I | E17: 110
B19: PP&E - Machinery | C19: P | D19: A | E19: 350.51
B20: PP&E - Other | C20: P | D20: A | E20: 146.71
B21: PP&E - IT | C21: P | D21: A | E21: 133.735
B22: PP&E - Vehicles | C22: P | D22: A | E22: 28.545
B23: PP&E | E23: 659.5
B25: Cash - Bank Accounts | C25: C | D25: A | E25: 125.4
B26: Cash - T-bills | C26: C | D26: A | E26: 59.4
B27: Cash - Cash at hand | C27: C | D27: A | E27: 35.2
B28: Cash | E28: 220
B30: Other assets | C30: O | D30: A | E30: 68
B31: Other assets | E31: 68
B33: Assets | E33: 1226.8
B35: Trade Payables - Discounters | C35: T | D35: L | E35: 19.981
B36: Trade Payables - Retail | C36: T | D36: L | E36: 15.847
B37: Trade Payables - Other | C37: T | D37: L | E37: 14.469
B38: Trade Payables - Grocery | C38: T | D38: L | E38: 10.335
B39: Trade Payables - Supermarkets | C39: T | D39: L | E39: 8.268
B40: Trade Payables | E40: 68.9
B42: Provisions - Taxes | C42: P | D42: L | E42: 17.507
B43: Provisions - Legal | C43: P | D43: L | E43: 6.601
B44: Provisions - Other | C44: P | D44: L | E44: 4.592
B45: Provisions | E45: 28.7
B47: Financial Liabilities vs. Banks | C47: F | D47: L | E47: 605
B48: Financial Liabilities | E48: 605
B50: Other liabilities | C50: O | D50: L | E50: 38.9
B51: Other liabilities | E51: 38.9
B53: Retained Earnings | C53: E | D53: E | E53: 450.125
...

Sheet Exercise -->
B13: Exercise -->

Sheet Workings
B3: Date | C3: Year | D3: Financials | E3: Amount | F3: Mapping
B4: 41640 | C4: =YEAR(B4) -> 2014 | D4: Revenue - Supermarkets | E4: 72 | F4: Revenue
B5: 41640 | C5: =YEAR(B5) -> 2014 | D5: Cogs - Supermarkets | E5: 47 | F5: Cost of goods sold
B6: 41640 | C6: =YEAR(B6) -> 2014 | D6: Revenue - Discounters | E6: 37 | F6: Revenue
B7: 41640 | C7: =YEAR(B7) -> 2014 | D7: Cogs - Discounters | E7: 20 | F7: Cost of goods sold
B8: 41640 | C8: =YEAR(B8) -> 2014 | D8: Revenue - Grocery | E8: 36 | F8: Revenue
B9: 41640 | C9: =YEAR(B9) -> 2014 | D9: Cogs - Grocery | E9: 17 | F9: Cost of goods sold
B10: 41640 | C10: =YEAR(B10) -> 2014 | D10: Revenue - Retail | E10: 57 | F10: Revenue
B11: 41640 | C11: =YEAR(B11) -> 2014 | D11: Cogs - Retail | E11: 32 | F11: Cost of goods sold
B12: 41640 | C12: =YEAR(B12) -> 2014 | D12: Operating expenses | E12: 95.4 | F12: Operating expenses
B13: 41640 | C13: =YEAR(B13) -> 2014 | D13: D&A | E13: 2 | F13: D&A
B14: 41640 | C14: =YEAR(B14) -> 2014 | D14: Interest expenses | E14: 5 | F14: Interest expenses
B15: 41640 | C15: =YEAR(B15) -> 2014 | D15: Taxes | E15: 17.29 | F15: Taxes
... B438: 42705 | C438: =YEAR(B438) -> 2016 | D438: Other revenue | E438: 628 | F438: Revenue

Sheet P&L
B1: P&L
B3: $ in million | C3: 2014 | D3: 2015 | E3: 2016 | G3: Var % 14-15 | H3: Var % 15-16
B4: Revenue | C4: =+SUMIFS(Workings!$E:$E,Workings!$F:$F,'P&L'!$B4,Workings!$C:$C,'P&L'!C$3) -> 2922 | D4: =+SUMIFS(Workings!$E:$E,Workings!$F:$F,'P&L'!$B4,Workings!$C:$C,'P&L'!D$3) -> 2984 | E4: =+SUMIFS(Workings!$E:$E,Workings!$F:$F,'P&L'!$B4,Workings!$C:$C,'P&L'!E$3) -> 3040 | G4: =D4/C4-1 -> 0.021218344 | H4: =E4/D4-1 -> 0.018766756
B5: Cost of goods sold | C5: =-1*SUMIFS(Workings!$E:$E,Workings!$F:$F,'P&L'!$B5,Workings!$C:$C,'P&L'!C$3) -> -1401 | D5: =-1*SUMIFS(Workings!$E:$E,Workings!$F:$F,'P&L'!$B5,Workings!$C:$C,'P&L'!D$3) -> -1383 | E5: =-1*SUMIFS(Workings!$E:$E,Workings!$F:$F,'P&L'!$B5,Workings!$C:$C,'P&L'!E$3) -> -1367 | G5: =D5/C5-1 -> -0.012847966 | H5: =E5/D5-1 -> -0.011569053
B6: Gross Profit | C6: =SUM(C4:C5) -> 1521 | D6: =SUM(D4:D5) -> 1601 | E6: =SUM(E4:E5) -> 1673 | G6: =D6/C6-1 -> 0.052596976 | H6: =E6/D6-1 -> 0.044971893
B7: Operating expenses | C7: =-1*SUMIFS(Workings!$E:$E,Workings!$F:$F,'P&L'!$B7,Workings!$C:$C,'P&L'!C$3) -> -1212.18 | D7: =-1*SUMIFS(Workings!$E:$E,Workings!$F:$F,'P&L'!$B7,Workings!$C:$C,'P&L'!D$3) -> -1245.34 | E7: =-1*SUMIFS(Workings!$E:$E,Workings!$F:$F,'P&L'!$B7,Workings!$C:$C,'P&L'!E$3) -> -1068.24 | G7: =D7/C7-1 -> 0.027355673 | H7: =E7/D7-1 -> -0.14221016
B8: EBITDA | C8: =SUM(C6:C7) -> 308.82 | D8: =SUM(D6:D7) -> 355.66 | E8: =SUM(E6:E7) -> 604.76 | G8: =D8/C8-1 -> 0.15167411 | H8: =E8/D8-1 -> 0.70038801
B9: D&A | C9: =-1*SUMIFS(Workings!$E:$E,Workings!$F:$F,'P&L'!$B9,Workings!$C:$C,'P&L'!C$3) -> -31 | D9: =-1*SUMIFS(Workings!$E:$E,Workings!$F:$F,'P&L'!$B9,Workings!$C:$C,'P&L'!D$3) -> -44 | E9: =-1*SUMIFS(Workings!$E:$E,Workings!$F:$F,'P&L'!$B9,Workings!$C:$C,'P&L'!E$3) -> -41 | G9: =D9/C9-1 -> 0.41935484 | H9: =E9/D9-1 -> -0.068181818
B10: EBIT | C10: =SUM(C8:C9) -> 277.82 | D10: =SUM(D8:D9) -> 311.66 | E10: =SUM(E8:E9) -> 563.76 | G10: =D10/C10-1 -> 0.12180549 | H10: =E10/D10-1 -> 0.80889431
B11: Interest expenses | C11: =-1*SUMIFS(Workings!$E:$E,Workings!$F:$F,'P&L'!$B11,Workings!$C:$C,'P&L'!C$3) -> -56 | D11: =-1*SUMIFS(Workings!$E:$E,Workings!$F:$F,'P&L'!$B11,Workings!$C:$C,'P&L'!D$3) -> -65 | E11: =-1*SUMIFS(Workings!$E:$E,Workings!$F:$F,'P&L'!$B11,Workings!$C:$C,'P&L'!E$3) -> -52 | G11: =D11/C11-1 -> 0.16071429 | H11: =E11/D11-1 -> -0.2
B12: EBT | C12: =SUM(C10:C11) -> 221.82 | D12: =SUM(D10:D11) -> 246.66 | E12: =SUM(E10:E11) -> 511.76 | G12: =D12/C12-1 -> 0.11198269 | H12: =E12/D12-1 -> 1.0747588
B13: Taxes | C13: =-1*SUMIFS(Workings!$E:$E,Workings!$F:$F,'P&L'!$B13,Workings!$C:$C,'P&L'!C$3) -> -207.52 | D13: =-1*SUMIFS(Workings!$E:$E,Workings!$F:$F,'P&L'!$B13,Workings!$C:$C,'P&L'!D$3) -> -209.98 | E13: =-1*SUMIFS(Workings!$E:$E,Workings!$F:$F,'P&L'!$B13,Workings!$C:$C,'P&L'!E$3) -> -208.58 | G13: =D13/C13-1 -> 0.011854279 | H13: =E13/D13-1 -> -0.0066673016
B14: Net Income | C14: =SUM(C12:C13) -> 14.3 | D14: =SUM(D12:D13) -> 36.68 | E14: =SUM(E12:E13) -> 303.18 | G14: =D14/C14-1 -> 1.565035 | H14: =E14/D14-1 -> 7.2655398
