Workbook

Sheet Input -->
B17: Input -->

Sheet Drivers
B1: Drivers
B3: Create a capital budgeting model that uses the inputs listed below. Calculate the project's feasibility in terms of NPV, IRR, and perform a sensitivity analysis.
B5: Selected case | C5: 1
B7: Installed capacity (MW)
B8: Best case | C8: 220
B9: Base case | C9: 200
B10: Worst case | C10: 180
B12: Capacity factor | C12: 0.25
B13: Days in one year | C13: 365
B14: Hours per day | C14: 24
B16: Inflation
B17: Expected long-term inflation Italy | C17: 0.01
B19: Price per MWh (EUR)
B20: Best case | C20: 220
B21: Base case | C21: 210
B22: Worst case | C22: 200
B24: Opex as a % of Revenue
B25: Best case | C25: -0.15
B26: Base case | C26: -0.16
B27: Worst case | C27: 0.17
B31: Estimated initial investment (in EUR)
B32: Best case | C32: 500000000
B33: Base case | C33: 510000000
B34: Worst case | C34: 520000000
B36: Useful life (years) | C36: 10
B37: Capex after year 1 | C37: 0.03
B39: Financing facilities
B40: Senior Facility (million EUR) | C40: 300000000
B41: Interest rate Senior Facility | C41: 0.04
B42: Repay Senior Facility in | C42: 10 years
B44: Repayment schedule | C44: 0 | D44: 1 | E44: 2 | F44: 3 | G44: 4 | H44: 5 | I44: 6 | J44: 7 | K44: 8 | L44: 9 | M44: 10 | N44: 11 | O44: 12
B45: Repayment % | C45: 0 | D45: 0 | E45: 0.05 | F45: 0.1 | G45: 0.1 | H45: 0.1 | I45: 0.1 | J45: 0.1 | K45: 0.1 | L45: 0.1 | M45: 0.1 | N45: 0.1 | O45: 0.05
B47: Tax rate | C47: 0.3
B48: Residual value of the project | C48: 100000000
B50: Comparable companies | C50: Leverage (D/E) | D50: Beta
B51: Company A | C51: 0.7 | D51: 0.5
B52: Company B | C52: 0.8 | D52: 0.4
B53: Company C | C53: 0.65 | D53: 0.35
B55: Company X beta | C55: 0.9
B58: Market risk premium | C58: 0.055
...

Sheet Workings -->
B17: Workings -->

Sheet Revenue
B1: Savings forecast
B3: Installed capacity (MW)
B4: Best case | C4: =Drivers!C8 -> 220
B5: Base case | C5: =Drivers!C9 -> 200
B6: Worst case | C6: =Drivers!C10 -> 180
B8: Capacity factor | C8: =Drivers!C12 -> 0.25
B9: =Drivers!B13 -> Days in one year | C9: =Drivers!C13 -> 365
B10: =Drivers!B14 -> Hours per day | C10: =Drivers!C14 -> 24
B13: Energy production MWh | C13: 1 | D13: 2 | E13: 3 | F13: 4 | G13: 5 | H13: 6 | I13: 7 | J13: 8 | K13: 9 | L13: 10
B14: Best case | C14: =$C4*Revenue!$C$8*Revenue!$C$9*Revenue!$C$10 -> 481800 | D14: =$C4*Revenue!$C$8*Revenue!$C$9*Revenue!$C$10 -> 481800 | E14: =$C4*Revenue!$C$8*Revenue!$C$9*Revenue!$C$10 -> 481800 | F14: =$C4*Revenue!$C$8*Revenue!$C$9*Revenue!$C$10 -> 481800 | G14: =$C4*Revenue!$C$8*Revenue!$C$9*Revenue!$C$10 -> 481800 | H14: =$C4*Revenue!$C$8*Revenue!$C$9*Revenue!$C$10 -> 481800 | I14: =$C4*Revenue!$C$8*Revenue!$C$9*Revenue!$C$10 -> 481800 | J14: =$C4*Revenue!$C$8*Revenue!$C$9*Revenue!$C$10 -> 481800 | ... L14: =$C4*Revenue!$C$8*Revenue!$C$9*Revenue!$C$10 -> 481800
B15: Base case | C15: =$C5*Revenue!$C$8*Revenue!$C$9*Revenue!$C$10 -> 438000 | D15: =$C5*Revenue!$C$8*Revenue!$C$9*Revenue!$C$10 -> 438000 | E15: =$C5*Revenue!$C$8*Revenue!$C$9*Revenue!$C$10 -> 438000 | F15: =$C5*Revenue!$C$8*Revenue!$C$9*Revenue!$C$10 -> 438000 | G15: =$C5*Revenue!$C$8*Revenue!$C$9*Revenue!$C$10 -> 438000 | H15: =$C5*Revenue!$C$8*Revenue!$C$9*Revenue!$C$10 -> 438000 | I15: =$C5*Revenue!$C$8*Revenue!$C$9*Revenue!$C$10 -> 438000 | J15: =$C5*Revenue!$C$8*Revenue!$C$9*Revenue!$C$10 -> 438000 | ... L15: =$C5*Revenue!$C$8*Revenue!$C$9*Revenue!$C$10 -> 438000
B16: Worst case | C16: =$C6*Revenue!$C$8*Revenue!$C$9*Revenue!$C$10 -> 394200 | D16: =$C6*Revenue!$C$8*Revenue!$C$9*Revenue!$C$10 -> 394200 | E16: =$C6*Revenue!$C$8*Revenue!$C$9*Revenue!$C$10 -> 394200 | F16: =$C6*Revenue!$C$8*Revenue!$C$9*Revenue!$C$10 -> 394200 | G16: =$C6*Revenue!$C$8*Revenue!$C$9*Revenue!$C$10 -> 394200 | H16: =$C6*Revenue!$C$8*Revenue!$C$9*Revenue!$C$10 -> 394200 | I16: =$C6*Revenue!$C$8*Revenue!$C$9*Revenue!$C$10 -> 394200 | J16: =$C6*Revenue!$C$8*Revenue!$C$9*Revenue!$C$10 -> 394200 | ... L16: =$C6*Revenue!$C$8*Revenue!$C$9*Revenue!$C$10 -> 394200
B17: Selected case | C17: =CHOOSE(Drivers!$C$5,Revenue!C14,Revenue!C15,Revenue!C16) -> 481800 | D17: =CHOOSE(Drivers!$C$5,Revenue!D14,Revenue!D15,Revenue!D16) -> 481800 | E17: =CHOOSE(Drivers!$C$5,Revenue!E14,Revenue!E15,Revenue!E16) -> 481800 | F17: =CHOOSE(Drivers!$C$5,Revenue!F14,Revenue!F15,Revenue!F16) -> 481800 | G17: =CHOOSE(Drivers!$C$5,Revenue!G14,Revenue!G15,Revenue!G16) -> 481800 | H17: =CHOOSE(Drivers!$C$5,Revenue!H14,Revenue!H15,Revenue!H16) -> 481800 | I17: =CHOOSE(Drivers!$C$5,Revenue!I14,Revenue!I15,Revenue!I16) -> 481800 | J17: =CHOOSE(Drivers!$C$5,Revenue!J14,Revenue!J15,Revenue!J16) -> 481800 | ... L17: =CHOOSE(Drivers!$C$5,Revenue!L14,Revenue!L15,Revenue!L16) -> 481800
B19: Expected long-term inflation | C19: =Drivers!C17 -> 0.01
B21: Price per MWh | C21: 1 | D21: 2 | E21: 3 | F21: 4 | G21: 5 | H21: 6 | I21: 7 | J21: 8 | K21: 9 | L21: 10
B22: Best case | C22: =Drivers!C20 -> 220 | D22: =C22*(1+$C$19) -> 222.2 | E22: =D22*(1+$C$19) -> 224.422 | F22: =E22*(1+$C$19) -> 226.66622 | G22: =F22*(1+$C$19) -> 228.93288 | H22: =G22*(1+$C$19) -> 231.22221 | I22: =H22*(1+$C$19) -> 233.53443 | J22: =I22*(1+$C$19) -> 235.86978 | K22: =J22*(1+$C$19) -> 238.22848 | L22: =K22*(1+$C$19) -> 240.61076
B23: Base case | C23: =Drivers!C21 -> 210 | D23: =C23*(1+$C$19) -> 212.1 | E23: =D23*(1+$C$19) -> 214.221 | F23: =E23*(1+$C$19) -> 216.36321 | G23: =F23*(1+$C$19) -> 218.52684 | H23: =G23*(1+$C$19) -> 220.71211 | I23: =H23*(1+$C$19) -> 222.91923 | J23: =I23*(1+$C$19) -> 225.14842 | K23: =J23*(1+$C$19) -> 227.39991 | L23: =K23*(1+$C$19) -> 229.67391
B24: Worst case | C24: =Drivers!C22 -> 200 | D24: =C24*(1+$C$19) -> 202 | E24: =D24*(1+$C$19) -> 204.02 | F24: =E24*(1+$C$19) -> 206.0602 | G24: =F24*(1+$C$19) -> 208.1208 | H24: =G24*(1+$C$19) -> 210.20201 | I24: =H24*(1+$C$19) -> 212.30403 | J24: =I24*(1+$C$19) -> 214.42707 | K24: =J24*(1+$C$19) -> 216.57134 | L24: =K24*(1+$C$19) -> 218.73705
B25: Selected case | C25: =CHOOSE(Drivers!$C$5,Revenue!C22,Revenue!C23,Revenue!C24) -> 220 | D25: =CHOOSE(Drivers!$C$5,Revenue!D22,Revenue!D23,Revenue!D24) -> 222.2 | E25: =CHOOSE(Drivers!$C$5,Revenue!E22,Revenue!E23,Revenue!E24) -> 224.422 | F25: =CHOOSE(Drivers!$C$5,Revenue!F22,Revenue!F23,Revenue!F24) -> 226.66622 | G25: =CHOOSE(Drivers!$C$5,Revenue!G22,Revenue!G23,Revenue!G24) -> 228.93288 | H25: =CHOOSE(Drivers!$C$5,Revenue!H22,Revenue!H23,Revenue!H24) -> 231.22221 | I25: =CHOOSE(Drivers!$C$5,Revenue!I22,Revenue!I23,Revenue!I24) -> 233.53443 | J25: =CHOOSE(Drivers!$C$5,Revenue!J22,Revenue!J23,Revenue!J24) -> 235.86978 | ... L25: =CHOOSE(Drivers!$C$5,Revenue!L22,Revenue!L23,Revenue!L24) -> 240.61076
B28: Revenue (EUR) | C28: 1 | D28: 2 | E28: 3 | F28: 4 | G28: 5 | H28: 6 | I28: 7 | J28: 8 | K28: 9 | L28: 10
B29: Best case | C29: =C14*C22 -> 105996000 | D29: =D14*D22 -> 107055960 | E29: =E14*E22 -> 1.0812652e+08 | F29: =F14*F22 -> 1.0920778e+08 | G29: =G14*G22 -> 1.1029986e+08 | H29: =H14*H22 -> 1.1140286e+08 | I29: =I14*I22 -> 1.1251689e+08 | J29: =J14*J22 -> 1.1364206e+08 | ... L29: =L14*L22 -> 1.1592626e+08
B30: Base case | C30: =C15*C23 -> 91980000 | D30: =D15*D23 -> 92899800 | E30: =E15*E23 -> 93828798 | F30: =F15*F23 -> 94767086 | G30: =G15*G23 -> 95714757 | H30: =H15*H23 -> 96671904 | I30: =I15*I23 -> 97638623 | J30: =J15*J23 -> 98615010 | ... L30: =L15*L23 -> 1.0059717e+08
B31: Worst case | C31: =C16*C24 -> 78840000 | D31: =D16*D24 -> 79628400 | E31: =E16*E24 -> 80424684 | F31: =F16*F24 -> 81228931 | G31: =G16*G24 -> 82041220 | H31: =H16*H24 -> 82861632 | I31: =I16*I24 -> 83690249 | J31: =J16*J24 -> 84527151 | ... L31: =L16*L24 -> 86226147
B32: Selected case | C32: =CHOOSE(Drivers!$C$5,Revenue!C29,Revenue!C30,Revenue!C31) -> 105996000 | D32: =CHOOSE(Drivers!$C$5,Revenue!D29,Revenue!D30,Revenue!D31) -> 107055960 | E32: =CHOOSE(Drivers!$C$5,Revenue!E29,Revenue!E30,Revenue!E31) -> 1.0812652e+08 | F32: =CHOOSE(Drivers!$C$5,Revenue!F29,Revenue!F30,Revenue!F31) -> 1.0920778e+08 | G32: =CHOOSE(Drivers!$C$5,Revenue!G29,Revenue!G30,Revenue!G31) -> 1.1029986e+08 | H32: =CHOOSE(Drivers!$C$5,Revenue!H29,Revenue!H30,Revenue!H31) -> 1.1140286e+08 | I32: =CHOOSE(Drivers!$C$5,Revenue!I29,Revenue!I30,Revenue!I31) -> 1.1251689e+08 | J32: =CHOOSE(Drivers!$C$5,Revenue!J29,Revenue!J30,Revenue!J31) -> 1.1364206e+08 | ... L32: =CHOOSE(Drivers!$C$5,Revenue!L29,Revenue!L30,Revenue!L31) -> 1.1592626e+08

Sheet Opex
B1: Opex
B3: Opex as a % of Revenue
B4: Best case | C4: =Drivers!C25 -> -0.15
B5: Base case | C5: =Drivers!C26 -> -0.16
B6: Worst case | C6: =-Drivers!C27 -> -0.17
B8: Capacity factor | C8: =Drivers!C12 -> 0.25
B9: =Drivers!B13 -> Days in one year | C9: =Drivers!C13 -> 365
B10: =Drivers!B14 -> Hours per day | C10: =Drivers!C14 -> 24
B13: Revenue | C13: 1 | D13: 2 | E13: 3 | F13: 4 | G13: 5 | H13: 6 | I13: 7 | J13: 8 | K13: 9 | L13: 10
B14: Best case | C14: =Revenue!C29 -> 105996000 | D14: =Revenue!D29 -> 107055960 | E14: =Revenue!E29 -> 1.0812652e+08 | F14: =Revenue!F29 -> 1.0920778e+08 | G14: =Revenue!G29 -> 1.1029986e+08 | H14: =Revenue!H29 -> 1.1140286e+08 | I14: =Revenue!I29 -> 1.1251689e+08 | J14: =Revenue!J29 -> 1.1364206e+08 | ... L14: =Revenue!L29 -> 1.1592626e+08
B15: Base case | C15: =Revenue!C30 -> 91980000 | D15: =Revenue!D30 -> 92899800 | E15: =Revenue!E30 -> 93828798 | F15: =Revenue!F30 -> 94767086 | G15: =Revenue!G30 -> 95714757 | H15: =Revenue!H30 -> 96671904 | I15: =Revenue!I30 -> 97638623 | J15: =Revenue!J30 -> 98615010 | ... L15: =Revenue!L30 -> 1.0059717e+08
B16: Worst case | C16: =Revenue!C31 -> 78840000 | D16: =Revenue!D31 -> 79628400 | E16: =Revenue!E31 -> 80424684 | F16: =Revenue!F31 -> 81228931 | G16: =Revenue!G31 -> 82041220 | H16: =Revenue!H31 -> 82861632 | I16: =Revenue!I31 -> 83690249 | J16: =Revenue!J31 -> 84527151 | ... L16: =Revenue!L31 -> 86226147
B17: Selected case | C17: =CHOOSE(Drivers!$C$5,Opex!C14,Opex!C15,Opex!C16) -> 105996000 | D17: =CHOOSE(Drivers!$C$5,Opex!D14,Opex!D15,Opex!D16) -> 107055960 | E17: =CHOOSE(Drivers!$C$5,Opex!E14,Opex!E15,Opex!E16) -> 1.0812652e+08 | F17: =CHOOSE(Drivers!$C$5,Opex!F14,Opex!F15,Opex!F16) -> 1.0920778e+08 | G17: =CHOOSE(Drivers!$C$5,Opex!G14,Opex!G15,Opex!G16) -> 1.1029986e+08 | H17: =CHOOSE(Drivers!$C$5,Opex!H14,Opex!H15,Opex!H16) -> 1.1140286e+08 | I17: =CHOOSE(Drivers!$C$5,Opex!I14,Opex!I15,Opex!I16) -> 1.1251689e+08 | J17: =CHOOSE(Drivers!$C$5,Opex!J14,Opex!J15,Opex!J16) -> 1.1364206e+08 | ... L17: =CHOOSE(Drivers!$C$5,Opex!L14,Opex!L15,Opex!L16) -> 1.1592626e+08
B19: Opex as a % of revenue | C19: 1 | D19: 2 | E19: 3 | F19: 4 | G19: 5 | H19: 6 | I19: 7 | J19: 8 | K19: 9 | L19: 10
B20: Best case | C20: =C14*$C4 -> -15899400 | D20: =D14*$C4 -> -16058394 | E20: =E14*$C4 -> -16218978 | F20: =F14*$C4 -> -16381168 | G20: =G14*$C4 -> -16544979 | H20: =H14*$C4 -> -16710429 | I20: =I14*$C4 -> -16877533 | J20: =J14*$C4 -> -17046309 | ... L20: =L14*$C4 -> -17388940
B21: Base case | C21: =C15*$C5 -> -14716800 | D21: =D15*$C5 -> -14863968 | E21: =E15*$C5 -> -15012608 | F21: =F15*$C5 -> -15162734 | G21: =G15*$C5 -> -15314361 | H21: =H15*$C5 -> -15467505 | I21: =I15*$C5 -> -15622180 | J21: =J15*$C5 -> -15778402 | ... L21: =L15*$C5 -> -16095547
B22: Worst case | C22: =C16*$C6 -> -13402800 | D22: =D16*$C6 -> -13536828 | E22: =E16*$C6 -> -13672196 | F22: =F16*$C6 -> -13808918 | G22: =G16*$C6 -> -13947007 | H22: =H16*$C6 -> -14086477 | I22: =I16*$C6 -> -14227342 | J22: =J16*$C6 -> -14369616 | ... L22: =L16*$C6 -> -14658445
B23: Selected case | C23: =CHOOSE(Drivers!$C$5,Opex!C20,Opex!C21,Opex!C22) -> -15899400 | D23: =CHOOSE(Drivers!$C$5,Opex!D20,Opex!D21,Opex!D22) -> -16058394 | E23: =CHOOSE(Drivers!$C$5,Opex!E20,Opex!E21,Opex!E22) -> -16218978 | F23: =CHOOSE(Drivers!$C$5,Opex!F20,Opex!F21,Opex!F22) -> -16381168 | G23: =CHOOSE(Drivers!$C$5,Opex!G20,Opex!G21,Opex!G22) -> -16544979 | H23: =CHOOSE(Drivers!$C$5,Opex!H20,Opex!H21,Opex!H22) -> -16710429 | I23: =CHOOSE(Drivers!$C$5,Opex!I20,Opex!I21,Opex!I22) -> -16877533 | J23: =CHOOSE(Drivers!$C$5,Opex!J20,Opex!J21,Opex!J22) -> -17046309 | ... L23: =CHOOSE(Drivers!$C$5,Opex!L20,Opex!L21,Opex!L22) -> -17388940

Sheet Fixed asset roll-forward
B1: Fixed asset roll-forward
B3: Estimated initial investment (in EUR)
B4: Best case | C4: =Drivers!C32 -> 500000000
B5: Base case | C5: =Drivers!C33 -> 510000000
B6: Worst case | C6: =Drivers!C34 -> 520000000
B8: =Drivers!B36 -> Useful life (years) | C8: =Drivers!C36 -> 10
B10: Investment plan | C10: 0 | D10: 1 | E10: 2 | F10: 3 | G10: 4 | H10: 5 | I10: 6 | J10: 7 | K10: 8 | L10: 9 | M10: 10
B11: Year 1 | C11: 1 | D11: =Drivers!$C$37 -> 0.03 | E11: =Drivers!$C$37 -> 0.03 | F11: =Drivers!$C$37 -> 0.03 | G11: =Drivers!$C$37 -> 0.03 | H11: =Drivers!$C$37 -> 0.03 | I11: =Drivers!$C$37 -> 0.03 | J11: =Drivers!$C$37 -> 0.03 | K11: =Drivers!$C$37 -> 0.03 | ... M11: =Drivers!$C$37 -> 0.03
B13: in EUR | D13: 1 | E13: 2 | F13: 3 | G13: 4 | H13: 5 | I13: 6 | J13: 7 | K13: 8 | L13: 9 | M13: 10
B14: Beginning PP&E | D14: =CHOOSE(Drivers!$C$5,'Fixed asset roll-forward'!$C4,'Fixed asset roll-forward'!$C5,'Fixed asset roll-forward'!$C6)*'Fixed asset roll-forward'!C11 -> 500000000 | E14: =D17 -> 465000000 | F14: =E17 -> 428500000 | G14: =F17 -> 390500000 | H14: =G17 -> 351000000 | I14: =H17 -> 310000000 | J14: =I17 -> 267500000 | K14: =J17 -> 223500000 | L14: =K17 -> 178000000 | M14: =L17 -> 131000000
B15: Capex | D15: =CHOOSE(Drivers!$C$5,'Fixed asset roll-forward'!$C4,'Fixed asset roll-forward'!$C5,'Fixed asset roll-forward'!$C6)*'Fixed asset roll-forward'!D11 -> 15000000 | E15: =CHOOSE(Drivers!$C$5,'Fixed asset roll-forward'!$C4,'Fixed asset roll-forward'!$C5,'Fixed asset roll-forward'!$C6)*'Fixed asset roll-forward'!E11 -> 15000000 | F15: =CHOOSE(Drivers!$C$5,'Fixed asset roll-forward'!$C4,'Fixed asset roll-forward'!$C5,'Fixed asset roll-forward'!$C6)*'Fixed asset roll-forward'!F11 -> 15000000 | G15: =CHOOSE(Drivers!$C$5,'Fixed asset roll-forward'!$C4,'Fixed asset roll-forward'!$C5,'Fixed asset roll-forward'!$C6)*'Fixed asset roll-forward'!G11 -> 15000000 | H15: =CHOOSE(Drivers!$C$5,'Fixed asset roll-forward'!$C4,'Fixed asset roll-forward'!$C5,'Fixed asset roll-forward'!$C6)*'Fixed asset roll-forward'!H11 -> 15000000 | I15: =CHOOSE(Drivers!$C$5,'Fixed asset roll-forward'!$C4,'Fixed asset roll-forward'!$C5,'Fixed asset roll-forward'!$C6)*'Fixed asset roll-forward'!I11 -> 15000000 | J15: =CHOOSE(Drivers!$C$5,'Fixed asset roll-forward'!$C4,'Fixed asset roll-forward'!$C5,'Fixed asset roll-forward'!$C6)*'Fixed asset roll-forward'!J11 -> 15000000 | K15: =CHOOSE(Drivers!$C$5,'Fixed asset roll-forward'!$C4,'Fixed asset roll-forward'!$C5,'Fixed asset roll-forward'!$C6)*'Fixed asset roll-forward'!K11 -> 15000000 | ... M15: =CHOOSE(Drivers!$C$5,'Fixed asset roll-forward'!$C4,'Fixed asset roll-forward'!$C5,'Fixed asset roll-forward'!$C6)*'Fixed asset roll-forward'!M11 -> 15000000
B16: D&A | D16: =D30 -> -50000000 | E16: =E30 -> -51500000 | F16: =F30 -> -53000000 | G16: =G30 -> -54500000 | H16: =H30 -> -56000000 | I16: =I30 -> -57500000 | J16: =J30 -> -59000000 | K16: =K30 -> -60500000 | ... M16: =M30 -> -63500000
B17: Ending PP&E | C17: =CHOOSE(Drivers!$C$5,'Fixed asset roll-forward'!$C4,'Fixed asset roll-forward'!$C5,'Fixed asset roll-forward'!$C6)*'Fixed asset roll-forward'!C11 -> 500000000 | D17: =SUM(D14:D16) -> 465000000 | E17: =SUM(E14:E16) -> 428500000 | F17: =SUM(F14:F16) -> 390500000 | G17: =SUM(G14:G16) -> 351000000 | H17: =SUM(H14:H16) -> 310000000 | I17: =SUM(I14:I16) -> 267500000 | J17: =SUM(J14:J16) -> 223500000 | K17: =SUM(K14:K16) -> 178000000 | ... M17: =SUM(M14:M16) -> 82500000
B19: D&A schedule (in EUR) | D19: 1 | E19: 2 | F19: 3 | G19: 4 | H19: 5 | I19: 6 | J19: 7 | K19: 8 | L19: 9 | M19: 10
B20: D&A Year 1 | D20: =-$D$14/10 -> -50000000 | E20: =-$D$14/10 -> -50000000 | F20: =-$D$14/10 -> -50000000 | G20: =-$D$14/10 -> -50000000 | H20: =-$D$14/10 -> -50000000 | I20: =-$D$14/10 -> -50000000 | J20: =-$D$14/10 -> -50000000 | K20: =-$D$14/10 -> -50000000 | ... M20: =-$D$14/10 -> -50000000
B21: D&A Year 2 | E21: =-$D$15/10 -> -1500000 | F21: =-$D$15/10 -> -1500000 | G21: =-$D$15/10 -> -1500000 | H21: =-$D$15/10 -> -1500000 | I21: =-$D$15/10 -> -1500000 | J21: =-$D$15/10 -> -1500000 | K21: =-$D$15/10 -> -1500000 | L21: =-$D$15/10 -> -1500000 | M21: =-$D$15/10 -> -1500000
B22: D&A Year 3 | F22: =-$E$15/10 -> -1500000 | G22: =-$E$15/10 -> -1500000 | H22: =-$E$15/10 -> -1500000 | I22: =-$E$15/10 -> -1500000 | J22: =-$E$15/10 -> -1500000 | K22: =-$E$15/10 -> -1500000 | L22: =-$E$15/10 -> -1500000 | M22: =-$E$15/10 -> -1500000
B23: D&A Year 4 | G23: =-$F$15/10 -> -1500000 | H23: =-$F$15/10 -> -1500000 | I23: =-$F$15/10 -> -1500000 | J23: =-$F$15/10 -> -1500000 | K23: =-$F$15/10 -> -1500000 | L23: =-$F$15/10 -> -1500000 | M23: =-$F$15/10 -> -1500000
B24: D&A Year 5 | H24: =-$G$15/10 -> -1500000 | I24: =-$G$15/10 -> -1500000 | J24: =-$G$15/10 -> -1500000 | K24: =-$G$15/10 -> -1500000 | L24: =-$G$15/10 -> -1500000 | M24: =-$G$15/10 -> -1500000
B25: D&A Year 6 | I25: =-$H$15/10 -> -1500000 | J25: =-$H$15/10 -> -1500000 | K25: =-$H$15/10 -> -1500000 | L25: =-$H$15/10 -> -1500000 | M25: =-$H$15/10 -> -1500000
B26: D&A Year 7 | J26: =-$I$15/10 -> -1500000 | K26: =-$I$15/10 -> -1500000 | L26: =-$I$15/10 -> -1500000 | M26: =-$I$15/10 -> -1500000
B27: D&A Year 8 | K27: =-$J$15/10 -> -1500000 | L27: =-$J$15/10 -> -1500000 | M27: =-$J$15/10 -> -1500000
B28: D&A Year 9 | L28: =-$K$15/10 -> -1500000 | M28: =-$K$15/10 -> -1500000
B29: D&A Year 10 | M29: =-$L$15/10 -> -1500000
B30: Total D&A | D30: =SUM(D20:D29) -> -50000000 | E30: =SUM(E20:E29) -> -51500000 | F30: =SUM(F20:F29) -> -53000000 | G30: =SUM(G20:G29) -> -54500000 | H30: =SUM(H20:H29) -> -56000000 | I30: =SUM(I20:I29) -> -57500000 | J30: =SUM(J20:J29) -> -59000000 | K30: =SUM(K20:K29) -> -60500000 | ... M30: =SUM(M20:M29) -> -63500000

Sheet Financing
B1: Financing
B3: Investment in Year 0 | C3: ='Fixed asset roll-forward'!$D$14 -> 500000000
B5: Financing facilities
B6: Debt Facility (EUR) | C6: =Drivers!C40 -> 300000000
B7: Interest rate Debt Facility | C7: =Drivers!C41 -> 0.04
B8: Repay Debt Facility in | C8: =Drivers!C42 -> 10 years
B10: in EUR | C10: 0 | D10: 1 | E10: 2 | F10: 3 | G10: 4 | H10: 5 | I10: 6 | J10: 7 | K10: 8 | L10: 9 | M10: 10
B11: Beginning Debt | C11: =C6 -> 300000000 | D11: =C14 -> 300000000 | E11: =D14 -> 300000000 | F11: =E14 -> 285000000 | G11: =F14 -> 255000000 | H11: =G14 -> 225000000 | I11: =H14 -> 195000000 | J11: =I14 -> 165000000 | K11: =J14 -> 135000000 | ... M11: =L14 -> 75000000
B12: Repayment | C12: =-$C$11*C13 -> 0 | D12: =-$D$11*D13 -> 0 | E12: =-$D$11*E13 -> -15000000 | F12: =-$D$11*F13 -> -30000000 | G12: =-$D$11*G13 -> -30000000 | H12: =-$D$11*H13 -> -30000000 | I12: =-$D$11*I13 -> -30000000 | J12: =-$D$11*J13 -> -30000000 | K12: =-$D$11*K13 -> -30000000 | ... M12: =-$D$11*M13 -> -30000000
B13: Repayment % | C13: 0 | D13: 0 | E13: 0.05 | F13: 0.1 | G13: 0.1 | H13: 0.1 | I13: 0.1 | J13: 0.1 | K13: 0.1 | L13: 0.1 | M13: 0.1
B14: Ending Debt | C14: =SUM(C11:C12) -> 300000000 | D14: =SUM(D11:D12) -> 300000000 | E14: =SUM(E11:E12) -> 285000000 | F14: =SUM(F11:F12) -> 255000000 | G14: =SUM(G11:G12) -> 225000000 | H14: =SUM(H11:H12) -> 195000000 | I14: =SUM(I11:I12) -> 165000000 | J14: =SUM(J11:J12) -> 135000000 | ... M14: =SUM(M11:M12) -> 45000000
B16: Interest expense | C16: =IF(C10=0,0,-C11*$C$7) -> 0 | D16: =IF(D10=0,0,-D11*$C$7) -> -12000000 | E16: =IF(E10=0,0,-E11*$C$7) -> -12000000 | F16: =IF(F10=0,0,-F11*$C$7) -> -11400000 | G16: =IF(G10=0,0,-G11*$C$7) -> -10200000 | H16: =IF(H10=0,0,-H11*$C$7) -> -9000000 | I16: =IF(I10=0,0,-I11*$C$7) -> -7800000 | J16: =IF(J10=0,0,-J11*$C$7) -> -6600000 | ... M16: =IF(M10=0,0,-M11*$C$7) -> -3000000
B18: Net Cash Flow | C18: ='Cash Flow'!C12 -> -500000000 | D18: ='Cash Flow'!D12 -> 54667620 | E18: ='Cash Flow'!E12 -> 40748296 | F18: ='Cash Flow'!F12 -> 27255279 | G18: ='Cash Flow'!G12 -> 29188632 | H18: ='Cash Flow'!H12 -> 31128418 | I18: ='Cash Flow'!I12 -> 33074702 | J18: ='Cash Flow'!J12 -> 35027549 | ... M18: ='Cash Flow'!M12 -> 40926127
B19: Equity financing | C19: =-(C14+C18) -> 200000000 | D19: =IF(D18>0,C19,C19-D18) -> 200000000 | E19: =IF(E18>0,D19,D19-E18) -> 200000000 | F19: =IF(F18>0,E19,E19-F18) -> 200000000 | G19: =IF(G18>0,F19,F19-G18) -> 200000000 | H19: =IF(H18>0,G19,G19-H18) -> 200000000 | I19: =IF(I18>0,H19,H19-I18) -> 200000000 | J19: =IF(J18>0,I19,I19-J18) -> 200000000 | K19: =IF(K18>0,J19,J19-K18) -> 200000000 | ... M19: =IF(M18>0,L19,L19-M18) -> 200000000

Sheet P&L
B1: P&L
B3: in EUR | C3: 1 | D3: 2 | E3: 3 | F3: 4 | G3: 5 | H3: 6 | I3: 7 | J3: 8 | K3: 9 | L3: 10
B4: Revenue | C4: =Revenue!C32 -> 105996000 | D4: =Revenue!D32 -> 107055960 | E4: =Revenue!E32 -> 1.0812652e+08 | F4: =Revenue!F32 -> 1.0920778e+08 | G4: =Revenue!G32 -> 1.1029986e+08 | H4: =Revenue!H32 -> 1.1140286e+08 | I4: =Revenue!I32 -> 1.1251689e+08 | J4: =Revenue!J32 -> 1.1364206e+08 | ... L4: =Revenue!L32 -> 1.1592626e+08
B5: Opex | C5: =Opex!C23 -> -15899400 | D5: =Opex!D23 -> -16058394 | E5: =Opex!E23 -> -16218978 | F5: =Opex!F23 -> -16381168 | G5: =Opex!G23 -> -16544979 | H5: =Opex!H23 -> -16710429 | I5: =Opex!I23 -> -16877533 | J5: =Opex!J23 -> -17046309 | ... L5: =Opex!L23 -> -17388940
B6: D&A | C6: ='Fixed asset roll-forward'!D16 -> -50000000 | D6: ='Fixed asset roll-forward'!E16 -> -51500000 | E6: ='Fixed asset roll-forward'!F16 -> -53000000 | F6: ='Fixed asset roll-forward'!G16 -> -54500000 | G6: ='Fixed asset roll-forward'!H16 -> -56000000 | H6: ='Fixed asset roll-forward'!I16 -> -57500000 | I6: ='Fixed asset roll-forward'!J16 -> -59000000 | J6: ='Fixed asset roll-forward'!K16 -> -60500000 | ... L6: ='Fixed asset roll-forward'!M16 -> -63500000
B7: EBIT | C7: =SUM(C4:C6) -> 40096600 | D7: =SUM(D4:D6) -> 39497566 | E7: =SUM(E4:E6) -> 38907542 | F7: =SUM(F4:F6) -> 38326617 | G7: =SUM(G4:G6) -> 37754883 | H7: =SUM(H4:H6) -> 37192432 | I7: =SUM(I4:I6) -> 36639356 | J7: =SUM(J4:J6) -> 36095750 | ... L7: =SUM(L4:L6) -> 35037325
B8: Interest expenses | C8: =Financing!D16 -> -12000000 | D8: =Financing!E16 -> -12000000 | E8: =Financing!F16 -> -11400000 | F8: =Financing!G16 -> -10200000 | G8: =Financing!H16 -> -9000000 | H8: =Financing!I16 -> -7800000 | I8: =Financing!J16 -> -6600000 | J8: =Financing!K16 -> -5400000 | ... L8: =Financing!M16 -> -3000000
B9: EBT | C9: =SUM(C7:C8) -> 28096600 | D9: =SUM(D7:D8) -> 27497566 | E9: =SUM(E7:E8) -> 27507542 | F9: =SUM(F7:F8) -> 28126617 | G9: =SUM(G7:G8) -> 28754883 | H9: =SUM(H7:H8) -> 29392432 | I9: =SUM(I7:I8) -> 30039356 | J9: =SUM(J7:J8) -> 30695750 | ... L9: =SUM(L7:L8) -> 32037325
B10: Taxes | C10: =IF(-'P&L'!C9*Drivers!$C$47>0,0,-'P&L'!C9*Drivers!$C$47) -> -8428980 | D10: =IF(-'P&L'!D9*Drivers!$C$47>0,0,-'P&L'!D9*Drivers!$C$47) -> -8249269.8 | E10: =IF(-'P&L'!E9*Drivers!$C$47>0,0,-'P&L'!E9*Drivers!$C$47) -> -8252262.5 | F10: =IF(-'P&L'!F9*Drivers!$C$47>0,0,-'P&L'!F9*Drivers!$C$47) -> -8437985.1 | G10: =IF(-'P&L'!G9*Drivers!$C$47>0,0,-'P&L'!G9*Drivers!$C$47) -> -8626465 | H10: =IF(-'P&L'!H9*Drivers!$C$47>0,0,-'P&L'!H9*Drivers!$C$47) -> -8817729.6 | I10: =IF(-'P&L'!I9*Drivers!$C$47>0,0,-'P&L'!I9*Drivers!$C$47) -> -9011806.9 | J10: =IF(-'P&L'!J9*Drivers!$C$47>0,0,-'P&L'!J9*Drivers!$C$47) -> -9208725 | ... L10: =IF(-'P&L'!L9*Drivers!$C$47>0,0,-'P&L'!L9*Drivers!$C$47) -> -9611197.4
B11: Net Income | C11: =SUM(C9:C10) -> 19667620 | D11: =SUM(D9:D10) -> 19248296 | E11: =SUM(E9:E10) -> 19255279 | F11: =SUM(F9:F10) -> 19688632 | G11: =SUM(G9:G10) -> 20128418 | H11: =SUM(H9:H10) -> 20574702 | I11: =SUM(I9:I10) -> 21027549 | J11: =SUM(J9:J10) -> 21487025 | ... L11: =SUM(L9:L10) -> 22426127

Sheet Cash Flow
B1: Cash Flow
B3: in EUR | C3: 0 | D3: 1 | E3: 2 | F3: 3 | G3: 4 | H3: 5 | I3: 6 | J3: 7 | K3: 8 | L3: 9 | M3: 10 | O3: Residual Value
B4: Revenue | C4: 0 | D4: =Revenue!C32 -> 105996000 | E4: =Revenue!D32 -> 107055960 | F4: =Revenue!E32 -> 1.0812652e+08 | G4: =Revenue!F32 -> 1.0920778e+08 | H4: =Revenue!G32 -> 1.1029986e+08 | I4: =Revenue!H32 -> 1.1140286e+08 | J4: =Revenue!I32 -> 1.1251689e+08 | K4: =Revenue!J32 -> 1.1364206e+08 | ... M4: =Revenue!L32 -> 1.1592626e+08
B5: Opex | D5: =Opex!C23 -> -15899400 | E5: =Opex!D23 -> -16058394 | F5: =Opex!E23 -> -16218978 | G5: =Opex!F23 -> -16381168 | H5: =Opex!G23 -> -16544979 | I5: =Opex!H23 -> -16710429 | J5: =Opex!I23 -> -16877533 | K5: =Opex!J23 -> -17046309 | ... M5: =Opex!L23 -> -17388940
B6: Taxes | C6: 0 | D6: ='P&L'!C10 -> -8428980 | E6: ='P&L'!D10 -> -8249269.8 | F6: ='P&L'!E10 -> -8252262.5 | G6: ='P&L'!F10 -> -8437985.1 | H6: ='P&L'!G10 -> -8626465 | I6: ='P&L'!H10 -> -8817729.6 | J6: ='P&L'!I10 -> -9011806.9 | K6: ='P&L'!J10 -> -9208725 | ... M6: ='P&L'!L10 -> -9611197.4
B7: Capex | C7: =-'Fixed asset roll-forward'!D14 -> -500000000 | D7: =-'Fixed asset roll-forward'!D15 -> -15000000 | E7: =-'Fixed asset roll-forward'!E15 -> -15000000 | F7: =-'Fixed asset roll-forward'!F15 -> -15000000 | G7: =-'Fixed asset roll-forward'!G15 -> -15000000 | H7: =-'Fixed asset roll-forward'!H15 -> -15000000 | I7: =-'Fixed asset roll-forward'!I15 -> -15000000 | J7: =-'Fixed asset roll-forward'!J15 -> -15000000 | K7: =-'Fixed asset roll-forward'!K15 -> -15000000 | ... M7: =-'Fixed asset roll-forward'!M15 -> -15000000
B8: Operating Cash Flow | C8: =SUM(C4:C7) -> -500000000 | D8: =SUM(D4:D7) -> 66667620 | E8: =SUM(E4:E7) -> 67748296 | F8: =SUM(F4:F7) -> 68655279 | G8: =SUM(G4:G7) -> 69388632 | H8: =SUM(H4:H7) -> 70128418 | I8: =SUM(I4:I7) -> 70874702 | J8: =SUM(J4:J7) -> 71627549 | ... M8: =SUM(M4:M7) -> 73926127
B9: Debt repayment | C9: 0 | D9: =Financing!D12 -> 0 | E9: =Financing!E12 -> -15000000 | F9: =Financing!F12 -> -30000000 | G9: =Financing!G12 -> -30000000 | H9: =Financing!H12 -> -30000000 | I9: =Financing!I12 -> -30000000 | J9: =Financing!J12 -> -30000000 | K9: =Financing!K12 -> -30000000 | ... M9: =Financing!M12 -> -30000000
B10: Interest expenses | C10: 0 | D10: =Financing!D16 -> -12000000 | E10: =Financing!E16 -> -12000000 | F10: =Financing!F16 -> -11400000 | G10: =Financing!G16 -> -10200000 | H10: =Financing!H16 -> -9000000 | I10: =Financing!I16 -> -7800000 | J10: =Financing!J16 -> -6600000 | K10: =Financing!K16 -> -5400000 | ... M10: =Financing!M16 -> -3000000
B11: Increase of equity | D11: =Financing!D19-Financing!C19 -> 0 | E11: =Financing!E19-Financing!D19 -> 0 | F11: =Financing!F19-Financing!E19 -> 0 | G11: =Financing!G19-Financing!F19 -> 0 | H11: =Financing!H19-Financing!G19 -> 0 | I11: =Financing!I19-Financing!H19 -> 0 | J11: =Financing!J19-Financing!I19 -> 0 | K11: =Financing!K19-Financing!J19 -> 0 | ... M11: =Financing!M19-Financing!L19 -> 0
B12: Net Cash Flow | C12: =SUM(C8:C11) -> -500000000 | D12: =SUM(D8:D10) -> 54667620 | E12: =SUM(E8:E10) -> 40748296 | F12: =SUM(F8:F10) -> 27255279 | G12: =SUM(G8:G10) -> 29188632 | H12: =SUM(H8:H10) -> 31128418 | I12: =SUM(I8:I10) -> 33074702 | J12: =SUM(J8:J10) -> 35027549 | K12: =SUM(K8:K10) -> 36987025 | ... M12: =SUM(M8:M10) -> 40926127 | O12: =Drivers!C48 -> 100000000

Sheet WACC
B1: WACC
B3: Cost of debt | C3: =Drivers!C41 -> 0.04
B4: Risk-free | C4: =Drivers!C59 -> 0.02
B5: Tax rate | C5: =Drivers!C47 -> 0.3
B6: Market risk premium | C6: =Drivers!C58 -> 0.055
B8: Comparable companies | C8: Leverage (D/E) | D8: Beta
B9: Company A | C9: =Drivers!C51 -> 0.7 | D9: =Drivers!D51 -> 0.5
B10: Company B | C10: =Drivers!C52 -> 0.8 | D10: =Drivers!D52 -> 0.4
B11: Company C | C11: =Drivers!C53 -> 0.65 | D11: =Drivers!D53 -> 0.35
B14: in EUR | C14: 0 | D14: 1 | E14: 2 | F14: 3 | G14: 4 | H14: 5 | I14: 6 | J14: 7 | K14: 8 | L14: 9 | M14: 10
B15: Debt financing | C15: =Financing!C14 -> 300000000 | D15: =Financing!D14 -> 300000000 | E15: =Financing!E14 -> 285000000 | F15: =Financing!F14 -> 255000000 | G15: =Financing!G14 -> 225000000 | H15: =Financing!H14 -> 195000000 | I15: =Financing!I14 -> 165000000 | J15: =Financing!J14 -> 135000000 | ... M15: =Financing!M14 -> 45000000
B16: Equity financing | C16: =Financing!C19 -> 200000000 | D16: =Financing!D19 -> 200000000 | E16: =Financing!E19 -> 200000000 | F16: =Financing!F19 -> 200000000 | G16: =Financing!G19 -> 200000000 | H16: =Financing!H19 -> 200000000 | I16: =Financing!I19 -> 200000000 | J16: =Financing!J19 -> 200000000 | ... M16: =Financing!M19 -> 200000000
B17: Total financing | C17: =SUM(C15:C16) -> 500000000 | D17: =SUM(D15:D16) -> 500000000 | E17: =SUM(E15:E16) -> 485000000 | F17: =SUM(F15:F16) -> 455000000 | G17: =SUM(G15:G16) -> 425000000 | H17: =SUM(H15:H16) -> 395000000 | I17: =SUM(I15:I16) -> 365000000 | J17: =SUM(J15:J16) -> 335000000 | ... M17: =SUM(M15:M16) -> 245000000
B19: Debt financing % | C19: =C15/C$17 -> 0.6 | D19: =D15/D$17 -> 0.6 | E19: =E15/E$17 -> 0.58762887 | F19: =F15/F$17 -> 0.56043956 | G19: =G15/G$17 -> 0.52941176 | H19: =H15/H$17 -> 0.49367089 | I19: =I15/I$17 -> 0.45205479 | J19: =J15/J$17 -> 0.40298507 | ... M19: =M15/M$17 -> 0.18367347
B20: Equity financing % | C20: =C16/C$17 -> 0.4 | D20: =D16/D$17 -> 0.4 | E20: =E16/E$17 -> 0.41237113 | F20: =F16/F$17 -> 0.43956044 | G20: =G16/G$17 -> 0.47058824 | H20: =H16/H$17 -> 0.50632911 | I20: =I16/I$17 -> 0.54794521 | J20: =J16/J$17 -> 0.59701493 | ... M20: =M16/M$17 -> 0.81632653
B21: Total financing % | C21: =SUM(C19:C20) -> 1 | D21: =SUM(D19:D20) -> 1 | E21: =SUM(E19:E20) -> 1 | F21: =SUM(F19:F20) -> 1 | G21: =SUM(G19:G20) -> 1 | H21: =SUM(H19:H20) -> 1 | I21: =SUM(I19:I20) -> 1 | J21: =SUM(J19:J20) -> 1 | ... M21: =SUM(M19:M20) -> 1
B24: Comparable companies:
B25: Average leverage | C25: =AVERAGE(C9:C11) -> 0.71666667
B26: Average beta | C26: =AVERAGE(D9:D11) -> 0.41666667
B28: Project beta:
B29: Debt / Equity | C29: =C19/C20 -> 1.5 | D29: =D19/D20 -> 1.5 | E29: =E19/E20 -> 1.425 | F29: =F19/F20 -> 1.275 | G29: =G19/G20 -> 1.125 | H29: =H19/H20 -> 0.975 | I29: =I19/I20 -> 0.825 | J29: =J19/J20 -> 0.675 | ... M29: =M19/M20 -> 0.225
B30: Beta unlevered | C30: =$C$26/((1+(1-$C$5)*($C$25))) -> 0.27746948 | D30: =$C$26/((1+(1-$C$5)*($C$25))) -> 0.27746948 | E30: =$C$26/((1+(1-$C$5)*($C$25))) -> 0.27746948 | F30: =$C$26/((1+(1-$C$5)*($C$25))) -> 0.27746948 | G30: =$C$26/((1+(1-$C$5)*($C$25))) -> 0.27746948 | H30: =$C$26/((1+(1-$C$5)*($C$25))) -> 0.27746948 | I30: =$C$26/((1+(1-$C$5)*($C$25))) -> 0.27746948 | J30: =$C$26/((1+(1-$C$5)*($C$25))) -> 0.27746948 | ... M30: =$C$26/((1+(1-$C$5)*($C$25))) -> 0.27746948
B31: Project beta: | C31: =C30*(1+(1-$C$5)*(C29)) -> 0.56881243 | D31: =D30*(1+(1-$C$5)*(D29)) -> 0.56881243 | E31: =E30*(1+(1-$C$5)*(E29)) -> 0.55424528 | F31: =F30*(1+(1-$C$5)*(F29)) -> 0.52511099 | G31: =G30*(1+(1-$C$5)*(G29)) -> 0.49597669 | H31: =H30*(1+(1-$C$5)*(H29)) -> 0.4668424 | I31: =I30*(1+(1-$C$5)*(I29)) -> 0.4377081 | J31: =J30*(1+(1-$C$5)*(J29)) -> 0.40857381 | ... M31: =M30*(1+(1-$C$5)*(M29)) -> 0.32117092
B33: Cost of equity | C33: =$C$4+$C$6*C31 -> 0.051284684 | D33: =$C$4+$C$6*D31 -> 0.051284684 | E33: =$C$4+$C$6*E31 -> 0.050483491 | F33: =$C$4+$C$6*F31 -> 0.048881104 | G33: =$C$4+$C$6*G31 -> 0.047278718 | H33: =$C$4+$C$6*H31 -> 0.045676332 | I33: =$C$4+$C$6*I31 -> 0.044073946 | J33: =$C$4+$C$6*J31 -> 0.042471559 | ... M33: =$C$4+$C$6*M31 -> 0.037664401
B35: WACC | C35: =C19*(1-$C$5)*$C$3+C20*C33 -> 0.037313873 | D35: =D19*(1-$C$5)*$C$3+D20*D33 -> 0.037313873 | E35: =E19*(1-$C$5)*$C$3+E20*E33 -> 0.037271543 | F35: =F19*(1-$C$5)*$C$3+F20*F33 -> 0.037178507 | G35: =G19*(1-$C$5)*$C$3+G20*G33 -> 0.037072338 | H35: =H19*(1-$C$5)*$C$3+H20*H33 -> 0.036950041 | I35: =I19*(1-$C$5)*$C$3+I20*I33 -> 0.036807641 | J35: =J19*(1-$C$5)*$C$3+J20*J33 -> 0.036639737 | ... M35: =M19*(1-$C$5)*$C$3+M20*M33 -> 0.035889307

Sheet Output -->
B17: Output -->

Sheet Discounted Cash Flows
B1: Discounted Cash Flows
B3: Selected case | C3: 1
B5: Residual Value | C5: ='Cash Flow'!O12-Financing!M14 -> 55000000
B7: in EUR | D7: 0 | E7: 1 | F7: 2 | G7: 3 | H7: 4 | I7: 5 | J7: 6 | K7: 7 | L7: 8 | M7: 9 | N7: 10
B8: Net Cash Flow | D8: =-Financing!C19 -> -200000000 | E8: ='Cash Flow'!D12 -> 54667620 | F8: ='Cash Flow'!E12 -> 40748296 | G8: ='Cash Flow'!F12 -> 27255279 | H8: ='Cash Flow'!G12 -> 29188632 | I8: ='Cash Flow'!H12 -> 31128418 | J8: ='Cash Flow'!I12 -> 33074702 | K8: ='Cash Flow'!J12 -> 35027549 | L8: ='Cash Flow'!K12 -> 36987025 | ... N8: ='Cash Flow'!M12 -> 40926127
B9: Residual value | N9: =C5 -> 55000000
B10: Net Cash Flow with Residual Value | D10: =D8+D9 -> -200000000 | E10: =E8+E9 -> 54667620 | F10: =F8+F9 -> 40748296 | G10: =G8+G9 -> 27255279 | H10: =H8+H9 -> 29188632 | I10: =I8+I9 -> 31128418 | J10: =J8+J9 -> 33074702 | K10: =K8+K9 -> 35027549 | ... N10: =N8+N9 -> 95926127
B11: Cost of equity | E11: =WACC!D33 -> 0.051284684 | F11: =WACC!E33 -> 0.050483491 | G11: =WACC!F33 -> 0.048881104 | H11: =WACC!G33 -> 0.047278718 | I11: =WACC!H33 -> 0.045676332 | J11: =WACC!I33 -> 0.044073946 | K11: =WACC!J33 -> 0.042471559 | L11: =WACC!K33 -> 0.040869173 | ... N11: =WACC!M33 -> 0.037664401
B12: Discounted Cash Flow | D12: =D8/(1+D11)^D7 -> -200000000 | E12: =E8/(1+E11)^E7 -> 52000777 | F12: =F8/(1+F11)^F7 -> 36925892 | G12: =G8/(1+G11)^G7 -> 23619563 | H12: =H8/(1+H11)^H7 -> 24264125 | I12: =I8/(1+I11)^I7 -> 24898355 | J12: =J8/(1+J11)^J7 -> 25533385 | K12: =K8/(1+K11)^K7 -> 26179434 | ... N12: =N8/(1+N11)^N7 -> 28276879
B13: Present Value Residual Value | N13: =N9/(1+N11)^N7 -> 38000868
B14: Discounted Cash Flow with Residual Value | D14: =SUM(D12:D13) -> -200000000 | E14: =SUM(E12:E13) -> 52000777 | F14: =SUM(F12:F13) -> 36925892 | G14: =SUM(G12:G13) -> 23619563 | H14: =SUM(H12:H13) -> 24264125 | I14: =SUM(I12:I13) -> 24898355 | J14: =SUM(J12:J13) -> 25533385 | K14: =SUM(K12:K13) -> 26179434 | ... N14: =SUM(N12:N13) -> 66277747
B16: Discounted Cash Flows (NPV) | C16: * | D16: =SUM(D14:N14) -> 1.3408758e+08
B18: IRR | D18: =IRR(D10:N10) -> 0.1535183
C21: Sensitivity analysis
D22: =D18 -> 0.1535183
C23: 70000000 | D23: 0.15801905
C24: 80000000 | D24: 0.16090509
C25: 85000000 | D25: 0.16231606
C26: 95000000 | D26: 0.16507731
C27: 115000000 | D27: 0.17037424
