Workbook

Sheet Cover
B9: Tesla
B10: Company analysis

Sheet Drivers
B1: Drivers
B3: Selected case | C3: 2
B4: Company | C4: Tesla
B5: Currency | C5: USD
B6: Domestic country | C6: United States
B7: 10-year treasury yield (Sep 27 2018) | C7: 0.0307
B8: Market risk premium US | C8: 0.05
B9: Company beta (Sep 27 2018) | C9: 0.78
B10: Tesla share price (Sep 27 2018) | C10: 307.8
B11: Bond Yield (Sep 19 2018) | C11: 0.075
B12: Corporate tax rate | C12: 0.3
B13: Expected inflation | C13: 0.02

Sheet Input -->
B14: Input -->

Sheet P&L Input
B1: P&L Input
B3: (in thousands) | C3: 2014 Act | D3: 2015 Act | E3: 2016 Act | F3: 2017 Act | G3: 2018 H1 Act
B4: Automotive revenues | C4: 3007012 | D4: 3740973 | E4: 6350766 | F4: 9641300 | G4: 6092998
B5: Energy generation and storage | C5: 4208 | D5: 14477 | E5: 181394 | F5: 1116266 | G5: 784430
B6: Services and other | C6: 187136 | D6: 290575 | E6: 467972 | F6: 1001185 | G6: 533554
B7: Total revenues | C7: =SUM(C4:C6) -> 3198356 | D7: =SUM(D4:D6) -> 4046025 | E7: =SUM(E4:E6) -> 7000132 | F7: =SUM(F4:F6) -> 11758751 | G7: =SUM(G4:G6) -> 7410982
B8: Automotive cost of revenues | C8: -2145749 | D8: -2823302 | E8: -4750081 | F8: -7432704 | G8: -4862547
B9: Energy generation and storage cost of revenues | C9: -4005 | D9: -12287 | E9: -178332 | F9: -874538 | G9: -705636
B10: Services and other cost of revenues | C10: -166931 | D10: -286933 | E10: -472462 | F10: -1229022 | G10: -767343
B11: Gross profit | C11: =SUM(C7:C10) -> 881671 | D11: =SUM(D7:D10) -> 923503 | E11: =SUM(E7:E10) -> 1599257 | F11: =SUM(F7:F10) -> 2222487 | G11: =SUM(G7:G10) -> 1075456
B12: Research and development | C12: -464700 | D12: -717900 | E12: -834408 | F12: -1378073 | G12: -753225
B13: Selling, general and administrative | C13: -603660 | D13: -922232 | E13: -1432189 | F13: -2476500 | G13: -1437163
B14: Restructuring and other | G14: -103434
B15: EBIT | C15: =SUM(C11:C14) -> -186689 | D15: =SUM(D11:D14) -> -716629 | E15: =SUM(E11:E14) -> -667340 | F15: =SUM(F11:F14) -> -1632086 | G15: =SUM(G11:G14) -> -1218366
B16: Interest income | C16: 1126 | D16: 1508 | E16: 8530 | F16: 19686 | G16: 10278
B17: Interest expense | C17: -100886 | D17: -118851 | E17: -198810 | F17: -471259 | G17: -313128
B18: Other income (expense), net | C18: 1813 | D18: -41652 | E18: 111272 | F18: -125373 | G18: 13195
B19: EBT | C19: =SUM(C15:C18) -> -284636 | D19: =SUM(D15:D18) -> -875624 | E19: =SUM(E15:E18) -> -746348 | F19: =SUM(F15:F18) -> -2209032 | G19: =SUM(G15:G18) -> -1508021
B20: Provision for income taxes | C20: -9404 | D20: -13039 | E20: -26698 | F20: -31546 | G20: -19312
B21: Net loss incl. minority interests | C21: =SUM(C19:C20) -> -294040 | D21: =SUM(D19:D20) -> -888663 | E21: =SUM(E19:E20) -> -773046 | F21: =SUM(F19:F20) -> -2240578 | G21: =SUM(G19:G20) -> -1527333
B22: Minority interests | C22: 0 | D22: 0 | E22: 98132 | F22: 279178 | G22: 100243
B23: Net loss | C23: =SUM(C21:C22) -> -294040 | D23: =SUM(D21:D22) -> -888663 | E23: =SUM(E21:E22) -> -674914 | F23: =SUM(F21:F22) -> -1961400 | G23: =SUM(G21:G22) -> -1427090
B25: KPIs
B26: Revenue % automotive y-o-y | D26: =D4/C4-1 -> 0.24408316 | E26: =E4/D4-1 -> 0.69762412 | F26: =F4/E4-1 -> 0.51813183
B27: Revenue % generation y-o-y | D27: =D5/C5-1 -> 2.4403517 | E27: =E5/D5-1 -> 11.529806 | F27: =F5/E5-1 -> 5.1538199
B28: Revenue % services y-o-y | D28: =D6/C6-1 -> 0.55274773 | E28: =E6/D6-1 -> 0.61050331 | F28: =F6/E6-1 -> 1.1394122
B29: GP% automotive | C29: =(C4+C8)/C4 -> 0.28641821 | D29: =(D4+D8)/D4 -> 0.24530276 | E29: =(E4+E8)/E4 -> 0.25204597 | F29: =(F4+F8)/F4 -> 0.22907658 | G29: =(G4+G8)/G4 -> 0.20194509
B30: GP% energy generation and automotive | C30: =(C5+C9)/C5 -> 0.048241445 | D30: =(D5+D9)/D5 -> 0.15127444 | E30: =(E5+E9)/E5 -> 0.016880382 | F30: =(F5+F9)/F5 -> 0.21655054 | G30: =(G5+G9)/G5 -> 0.10044746
B31: GP% services and other | C31: =(C6+C10)/C6 -> 0.1079696 | D31: =(D6+D10)/D6 -> 0.012533769 | E31: =(E6+E10)/E6 -> -0.0095945911 | F31: =(F6+F10)/F6 -> -0.22756733 | G31: =(G6+G10)/G6 -> -0.43817308
B32: Overall GP% | C32: =C11/C7 -> 0.27566381 | D32: =D11/D7 -> 0.22824945 | E32: =E11/E7 -> 0.22846098 | F32: =F11/F7 -> 0.18900706 | G32: =G11/G7 -> 0.14511653
B33: EBIT % | C33: =C15/C7 -> -0.0583703 | D33: =D15/D7 -> -0.17711927 | E33: =E15/E7 -> -0.095332488 | F33: =F15/F7 -> -0.13879756 | G33: =G15/G7 -> -0.16440008
B34: Net loss % | C34: =C23/C7 -> -0.091934731 | D34: =D23/D7 -> -0.21963853 | E34: =E23/E7 -> -0.096414468 | F34: =F23/F7 -> -0.16680343 | G34: =G23/G7 -> -0.19256422
B35: ROA | C35: =C23/'Balance Sheet Input'!C17 -> -0.050429908 | D35: =D23/'Balance Sheet Input'!D17 -> -0.11014746 | E35: =E23/'Balance Sheet Input'!E17 -> -0.029779021 | F35: =F23/'Balance Sheet Input'!F17 -> -0.068447899 | G35: =G23/'Balance Sheet Input'!G17 -> -0.051131852
B36: ROE | C36: =C23/'Balance Sheet Input'!C31 -> -0.32251483 | D36: =D23/'Balance Sheet Input'!D31 -> -0.82002373 | E36: =E23/'Balance Sheet Input'!E31 -> -0.14200013 | F36: =F23/'Balance Sheet Input'!F31 -> -0.46289544 | G36: =G23/'Balance Sheet Input'!G31 -> -0.32098601

Sheet Balance Sheet Input
B1: Balance Sheet Input
B3: (in thousands) | C3: 31 Dec 2014 | D3: 31 Dec 2015 | E3: 31 Dec 2016 | F3: 31 Dec 2017 | G3: 30 Jun 2018
B4: Cash and cash equivalents | C4: 1905713 | D4: 1196908 | E4: 3393216 | F4: 3367914 | G4: 2236424
B5: Restricted cash and marketable securities | C5: 17947 | D5: 22628 | E5: 105519 | F5: 155323 | G5: 146822
B6: Accounts receivable, net | C6: 226604 | D6: 168965 | E6: 499142 | F6: 515381 | G6: 569874
B7: Inventory | C7: 953675 | D7: 1277838 | E7: 2067454 | F7: 2263537 | G7: 3324643
B8: Prepaid expenses and other current assets | C8: 76134 | D8: 115667 | E8: 194465 | F8: 268365 | G8: 422034
B9: Total current assets | C9: =SUM(C4:C8) -> 3180073 | D9: =SUM(D4:D8) -> 2782006 | E9: =SUM(E4:E8) -> 6259796 | F9: =SUM(F4:F8) -> 6570520 | G9: =SUM(G4:G8) -> 6699797
B10: Operating lease vehicles, net | C10: 766744 | D10: 1791403 | E10: 3134080 | F10: 4116604 | G10: 2282047
B11: Solar energy systems, leased and to be leased, net | C11: 0 | D11: 0 | E11: 5919880 | F11: 6347490 | G11: 6340031
B12: Property, plant and equipment, net | C12: 1829267 | D12: 3403334 | E12: 5982957 | F12: 10027522 | G12: 10969348
B13: Intangible assets, net | C13: 0 | D13: 12816 | E13: 376145 | F13: 361502 | G13: 364690
B14: portion | C14: 0 | D14: 0 | E14: 506302 | F14: =456652+60237 -> 516889 | G14: 434841
B15: Restricted cash, net of current portion | C15: 11374 | D15: 31522 | E15: 268165 | F15: 441722 | G15: 399992
B16: Other assets | C16: 43209 | D16: 46858 | E16: 216751 | F16: 273123 | G16: 419254
B17: Total assets | C17: =SUM(C9:C16) -> 5830667 | D17: =SUM(D9:D16) -> 8067939 | E17: =SUM(E9:E16) -> 22664076 | F17: =SUM(F9:F16) -> 28655372 | G17: =SUM(G9:G16) -> 27910000
B18: Accounts payable | C18: 777946 | D18: 916148 | E18: 1860341 | F18: 2390250 | G18: 3030493
B19: Accrued liabilities | C19: 268883 | D19: 422798 | E19: 1210028 | F19: 1731366 | G19: 1814979
B20: Deferred revenue | C20: 191651 | D20: 423961 | E20: 763126 | F20: 1015253 | G20: 576321
B21: Resale value guarantees | C21: 0 | D21: 136831 | E21: 179504 | F21: 787333 | G21: 674255
B22: Customer deposits | C22: 257587 | D22: 283370 | E22: 663859 | F22: 853919 | G22: 942129
B23: Current portion of long-term debt and capital leases | C23: 611099 | D23: 627927 | E23: 984211 | F23: 796549 | G23: 2103185
B24: Current portion of solar bonds issued to related | C24: 0
B25: parties | C25: 0 | D25: 0 | E25: 165936 | F25: 100000 | G25: 0
B26: Total current liabilities | C26: 2107166 | D26: 2811035 | E26: 5827005 | F26: =SUM(F18:F25) -> 7674670 | G26: =SUM(G18:G25) -> 9141362
B27: Long-term debt and capital leases, net of current
B28: portion | C28: 1818785 | D28: 2021093 | E28: 5860049 | F28: 9415700 | G28: 9513390
B29: Other liabilities | C29: 993006 | D29: 2152107 | E29: 5438936 | F29: 6330414 | G29: =795820+584857+2607458 -> 3988135
B30: Total liabilities | C30: =SUM(C26:C29) -> 4918957 | D30: =SUM(D26:D29) -> 6984235 | E30: =SUM(E26:E29) -> 17125990 | F30: =SUM(F26:F29) -> 23420784 | G30: =SUM(G26:G29) -> 22642887
B31: Total stockholders' equity | C31: 911710 | D31: 1083704 | E31: 4752911 | F31: 4237242 | G31: =3906421+539536 -> 4445957
B32: Noncontrolling interests in subsidiaries | C32: 0 | D32: 0 | E32: 785175 | F32: 997346 | G32: 821156
B33: Total liabilities and equity | C33: =C30+C31+C32 -> 5830667 | D33: =D30+D31+D32 -> 8067939 | E33: =E30+E31+E32 -> 22664076 | F33: =F30+F31+F32 -> 28655372 | G33: =G30+G31+G32 -> 27910000
B35: KPIs
B36: Liquidity ratios
B37: Quick ratio
B38: Current ratio
B39: DSO
B40: DIO
B41: DPO
B42: Net Trading Cycle
...
